<mujoco model="cart-pole">
  <include file="./common/skybox.xml"/>
  <include file="./common/visual.xml"/>
  <include file="./common/materials.xml"/>

  <option timestep="0.01" integrator="RK4">
    <flag contact="disable" energy="enable"/>
  </option>

  <default>
    <default class="pole">
      <joint type="hinge" axis="0 1 0"  damping="2e-4"/>
      <geom type="capsule" fromto="0 0 0 0 0 1" size="0.045" material="self" mass=".1"/>
    </default>
  </default>

  <worldbody>
    <light name="light1" pos="0 0 6"/>
    <light name="light2" pos="3 0 6"/>
    <camera name="fixed" pos="1.5 -4 1" zaxis="0 -1 0"/>
    <camera name="lookatcart" mode="targetbody" target="cart" pos="0 -2 2"/>
    <geom name="floor" pos="1.5 0 -.05" size="6 4 .2" type="plane" material="grid"/>
    <geom name="rail1" type="capsule" pos="1.5  .07 1" zaxis="1 0 0" size="0.02 4" material="decoration" />
    <geom name="rail2" type="capsule" pos="1.5 -.07 1" zaxis="1 0 0" size="0.02 4" material="decoration" />
    <body name="cart" pos="0 0 1">
      <joint name="slider" type="slide" limited="true" axis="1 0 0" range="-5 5" solreflimit=".08 1" damping="0.001"/>
      <geom name="cart" type="box" size="0.2 0.15 0.1" material="self"  mass="0.1"/>
      <body name="pole_1" childclass="pole">
        <joint name="hinge_1"/>
        <geom name="pole_1"/>
        <site name="pole_tip" pos="0 0 1" size="0.05" rgba="0.5 0.2 0.1 0.8"/>
      </body>
    </body>
    <site name="goal" size="0.05" rgba="0.2 0.8 0.2 0.8" pos="4. 0 2"/>
  </worldbody>

  <actuator>
    <motor name="slide" joint="slider" gear="2" ctrllimited="true" ctrlrange="-1 1" />
  </actuator>
</mujoco>
